


Loading model.

Cannot feed value of shape (1, 96, 128, 1) for Tensor 'inputs:0', which has shape '(?, 600, 1024, 3)'Traceback (most recent call last):
  File "C:/Users/admin/Documents/GeneralProjectData/Projects/NeuralNetworks.TF/Net/GUI/Demo/Demo.py", line 397, in evaluate
    self.is_train: False
  File "C:\Users\admin\Anaconda3\envs\tensorflow\lib\site-packages\tensorflow\python\framework\ops.py", line 656, in eval
    return _eval_using_default_session(self, feed_dict, self.graph, session)
  File "C:\Users\admin\Anaconda3\envs\tensorflow\lib\site-packages\tensorflow\python\framework\ops.py", line 4901, in _eval_using_default_session
    return session.run(tensors, feed_dict)
  File "C:\Users\admin\Anaconda3\envs\tensorflow\lib\site-packages\tensorflow\python\client\session.py", line 905, in run
    run_metadata_ptr)
  File "C:\Users\admin\Anaconda3\envs\tensorflow\lib\site-packages\tensorflow\python\client\session.py", line 1113, in _run
    str(subfeed_t.get_shape())))
ValueError: Cannot feed value of shape (1, 96, 128, 1) for Tensor 'inputs:0', which has shape '(?, 600, 1024, 3)'
'NoneType' object is not iterableTraceback (most recent call last):
  File "C:/Users/admin/Documents/GeneralProjectData/Projects/NeuralNetworks.TF/Net/GUI/Demo/Demo.py", line 178, in OnRecognizeClick
    result, coord = self.TFSession.evaluate(self.imageContainer.image_array)
TypeError: 'NoneType' object is not iterable
Cannot feed value of shape (1, 96, 128, 1) for Tensor 'inputs:0', which has shape '(?, 600, 1024, 3)'Traceback (most recent call last):
  File "C:/Users/admin/Documents/GeneralProjectData/Projects/NeuralNetworks.TF/Net/GUI/Demo/Demo.py", line 397, in evaluate
    self.is_train: False
  File "C:\Users\admin\Anaconda3\envs\tensorflow\lib\site-packages\tensorflow\python\framework\ops.py", line 656, in eval
    return _eval_using_default_session(self, feed_dict, self.graph, session)
  File "C:\Users\admin\Anaconda3\envs\tensorflow\lib\site-packages\tensorflow\python\framework\ops.py", line 4901, in _eval_using_default_session
    return session.run(tensors, feed_dict)
  File "C:\Users\admin\Anaconda3\envs\tensorflow\lib\site-packages\tensorflow\python\client\session.py", line 905, in run
    run_metadata_ptr)
  File "C:\Users\admin\Anaconda3\envs\tensorflow\lib\site-packages\tensorflow\python\client\session.py", line 1113, in _run
    str(subfeed_t.get_shape())))
ValueError: Cannot feed value of shape (1, 96, 128, 1) for Tensor 'inputs:0', which has shape '(?, 600, 1024, 3)'
'NoneType' object is not iterableTraceback (most recent call last):
  File "C:/Users/admin/Documents/GeneralProjectData/Projects/NeuralNetworks.TF/Net/GUI/Demo/Demo.py", line 178, in OnRecognizeClick
    result, coord = self.TFSession.evaluate(self.imageContainer.image_array)
TypeError: 'NoneType' object is not iterable



Loading model.




Loading model.




Loading model.




Loading model.




Loading model.

'TFSessionHolder' object has no attribute 'y'Traceback (most recent call last):
  File "C:/Users/admin/Documents/GeneralProjectData/Projects/NeuralNetworks.TF/Net/GUI/Demo/Demo.py", line 399, in evaluate
    self.w = self.y.eval(
AttributeError: 'TFSessionHolder' object has no attribute 'y'
'NoneType' object is not iterableTraceback (most recent call last):
  File "C:/Users/admin/Documents/GeneralProjectData/Projects/NeuralNetworks.TF/Net/GUI/Demo/Demo.py", line 180, in OnRecognizeClick
    result, coords = self.TFSession.evaluate(self.imageContainer.image_array)
TypeError: 'NoneType' object is not iterable



Loading model.

only size-1 arrays can be converted to Python scalarsTraceback (most recent call last):
  File "C:/Users/admin/Documents/GeneralProjectData/Projects/NeuralNetworks.TF/Net/GUI/Demo/Demo.py", line 197, in OnRecognizeClick
    coord[:, 0] = int(coord[:, 0] / 1024 * scalingX)
TypeError: only size-1 arrays can be converted to Python scalars



Loading model.

only size-1 arrays can be converted to Python scalarsTraceback (most recent call last):
  File "C:/Users/admin/Documents/GeneralProjectData/Projects/NeuralNetworks.TF/Net/GUI/Demo/Demo.py", line 197, in OnRecognizeClick
    coord[:, 0] = int(coord[:, 0] / 1024 * scalingX)
TypeError: only size-1 arrays can be converted to Python scalars
only size-1 arrays can be converted to Python scalarsTraceback (most recent call last):
  File "C:/Users/admin/Documents/GeneralProjectData/Projects/NeuralNetworks.TF/Net/GUI/Demo/Demo.py", line 197, in OnRecognizeClick
    coord[:, 0] = int(coord[:, 0] / 1024 * scalingX)
TypeError: only size-1 arrays can be converted to Python scalars
only size-1 arrays can be converted to Python scalarsTraceback (most recent call last):
  File "C:/Users/admin/Documents/GeneralProjectData/Projects/NeuralNetworks.TF/Net/GUI/Demo/Demo.py", line 197, in OnRecognizeClick
    coord[:, 0] = int(coord[:, 0] / 1024 * scalingX)
TypeError: only size-1 arrays can be converted to Python scalars



Loading model.




Loading model.




Loading model.




Loading model.




Loading model.




Loading model.




Loading model.




Loading model.




Loading model.




Loading model.




Loading model.




Loading model.




Loading model.




Loading model.




Loading model.




Loading model.

"The name 'Placeholder:0' refers to a Tensor which does not exist. The operation, 'Placeholder', does not exist in the graph."Traceback (most recent call last):
  File "C:/Users/admin/Documents/GeneralProjectData/Projects/NeuralNetworks.TF/Net/GUI/Demo/Demo.py", line 377, in load_model
    self.x = self.graph.get_tensor_by_name('Placeholder:0')
  File "C:\Users\admin\Anaconda3\envs\tensorflow\lib\site-packages\tensorflow\python\framework\ops.py", line 3635, in get_tensor_by_name
    return self.as_graph_element(name, allow_tensor=True, allow_operation=False)
  File "C:\Users\admin\Anaconda3\envs\tensorflow\lib\site-packages\tensorflow\python\framework\ops.py", line 3459, in as_graph_element
    return self._as_graph_element_locked(obj, allow_tensor, allow_operation)
  File "C:\Users\admin\Anaconda3\envs\tensorflow\lib\site-packages\tensorflow\python\framework\ops.py", line 3501, in _as_graph_element_locked
    "graph." % (repr(name), repr(op_name)))
KeyError: "The name 'Placeholder:0' refers to a Tensor which does not exist. The operation, 'Placeholder', does not exist in the graph."



Loading model.




Loading model.




Loading model.

"The name 'inputs:0' refers to a Tensor which does not exist. The operation, 'inputs', does not exist in the graph."Traceback (most recent call last):
  File "C:/Users/admin/Documents/GeneralProjectData/Projects/NeuralNetworks.TF/Net/GUI/Demo/Demo.py", line 377, in load_model
    self.x = self.graph.get_tensor_by_name('inputs:0')
  File "C:\Users\admin\Anaconda3\envs\tensorflow\lib\site-packages\tensorflow\python\framework\ops.py", line 3635, in get_tensor_by_name
    return self.as_graph_element(name, allow_tensor=True, allow_operation=False)
  File "C:\Users\admin\Anaconda3\envs\tensorflow\lib\site-packages\tensorflow\python\framework\ops.py", line 3459, in as_graph_element
    return self._as_graph_element_locked(obj, allow_tensor, allow_operation)
  File "C:\Users\admin\Anaconda3\envs\tensorflow\lib\site-packages\tensorflow\python\framework\ops.py", line 3501, in _as_graph_element_locked
    "graph." % (repr(name), repr(op_name)))
KeyError: "The name 'inputs:0' refers to a Tensor which does not exist. The operation, 'inputs', does not exist in the graph."



Loading model.




Loading model.




Loading model.




Loading model.




Loading model.




Loading model.

Assign requires shapes of both tensors to match. lhs shape= [1,1,512,18] rhs shape= [1,1,512,12]
	 [[Node: save/Assign_7 = Assign[T=DT_FLOAT, _class=["loc:@rpn_cls/weights"], use_locking=true, validate_shape=true, _device="/job:localhost/replica:0/task:0/device:GPU:0"](rpn_cls/weights, save/RestoreV2/_35)]]
	 [[Node: save/RestoreV2/_10 = _Send[T=DT_FLOAT, client_terminated=false, recv_device="/job:localhost/replica:0/task:0/device:GPU:0", send_device="/job:localhost/replica:0/task:0/device:CPU:0", send_device_incarnation=1, tensor_name="edge_16_save/RestoreV2", _device="/job:localhost/replica:0/task:0/device:CPU:0"](save/RestoreV2:5)]]

Caused by op 'save/Assign_7', defined at:
  File "C:/Users/admin/Documents/GeneralProjectData/Projects/NeuralNetworks.TF/Net/GUI/Demo/Demo.py", line 457, in <module>
    main()
  File "C:/Users/admin/Documents/GeneralProjectData/Projects/NeuralNetworks.TF/Net/GUI/Demo/Demo.py", line 453, in main
    application.exec()
  File "C:/Users/admin/Documents/GeneralProjectData/Projects/NeuralNetworks.TF/Net/GUI/Demo/Demo.py", line 168, in OnLoadModelMetaClick
    result = self.TFSession.load_model(FullFolderNameToModel=folderName, FullMetaFileName=fullName)
  File "C:/Users/admin/Documents/GeneralProjectData/Projects/NeuralNetworks.TF/Net/GUI/Demo/Demo.py", line 371, in load_model
    self.saver = tf.train.import_meta_graph(FullMetaFileName)
  File "C:\Users\admin\Anaconda3\envs\tensorflow\lib\site-packages\tensorflow\python\training\saver.py", line 1909, in import_meta_graph
    **kwargs)
  File "C:\Users\admin\Anaconda3\envs\tensorflow\lib\site-packages\tensorflow\python\framework\meta_graph.py", line 737, in import_scoped_meta_graph
    producer_op_list=producer_op_list)
  File "C:\Users\admin\Anaconda3\envs\tensorflow\lib\site-packages\tensorflow\python\util\deprecation.py", line 432, in new_func
    return func(*args, **kwargs)
  File "C:\Users\admin\Anaconda3\envs\tensorflow\lib\site-packages\tensorflow\python\framework\importer.py", line 553, in import_graph_def
    op_def=op_def)
  File "C:\Users\admin\Anaconda3\envs\tensorflow\lib\site-packages\tensorflow\python\framework\ops.py", line 3271, in create_op
    op_def=op_def)
  File "C:\Users\admin\Anaconda3\envs\tensorflow\lib\site-packages\tensorflow\python\framework\ops.py", line 1650, in __init__
    self._traceback = self._graph._extract_stack()  # pylint: disable=protected-access

InvalidArgumentError (see above for traceback): Assign requires shapes of both tensors to match. lhs shape= [1,1,512,18] rhs shape= [1,1,512,12]
	 [[Node: save/Assign_7 = Assign[T=DT_FLOAT, _class=["loc:@rpn_cls/weights"], use_locking=true, validate_shape=true, _device="/job:localhost/replica:0/task:0/device:GPU:0"](rpn_cls/weights, save/RestoreV2/_35)]]
	 [[Node: save/RestoreV2/_10 = _Send[T=DT_FLOAT, client_terminated=false, recv_device="/job:localhost/replica:0/task:0/device:GPU:0", send_device="/job:localhost/replica:0/task:0/device:CPU:0", send_device_incarnation=1, tensor_name="edge_16_save/RestoreV2", _device="/job:localhost/replica:0/task:0/device:CPU:0"](save/RestoreV2:5)]]
Traceback (most recent call last):
  File "C:\Users\admin\Anaconda3\envs\tensorflow\lib\site-packages\tensorflow\python\client\session.py", line 1361, in _do_call
    return fn(*args)
  File "C:\Users\admin\Anaconda3\envs\tensorflow\lib\site-packages\tensorflow\python\client\session.py", line 1340, in _run_fn
    target_list, status, run_metadata)
  File "C:\Users\admin\Anaconda3\envs\tensorflow\lib\site-packages\tensorflow\python\framework\errors_impl.py", line 516, in __exit__
    c_api.TF_GetCode(self.status.status))
tensorflow.python.framework.errors_impl.InvalidArgumentError: Assign requires shapes of both tensors to match. lhs shape= [1,1,512,18] rhs shape= [1,1,512,12]
	 [[Node: save/Assign_7 = Assign[T=DT_FLOAT, _class=["loc:@rpn_cls/weights"], use_locking=true, validate_shape=true, _device="/job:localhost/replica:0/task:0/device:GPU:0"](rpn_cls/weights, save/RestoreV2/_35)]]
	 [[Node: save/RestoreV2/_10 = _Send[T=DT_FLOAT, client_terminated=false, recv_device="/job:localhost/replica:0/task:0/device:GPU:0", send_device="/job:localhost/replica:0/task:0/device:CPU:0", send_device_incarnation=1, tensor_name="edge_16_save/RestoreV2", _device="/job:localhost/replica:0/task:0/device:CPU:0"](save/RestoreV2:5)]]

During handling of the above exception, another exception occurred:

Traceback (most recent call last):
  File "C:/Users/admin/Documents/GeneralProjectData/Projects/NeuralNetworks.TF/Net/GUI/Demo/Demo.py", line 375, in load_model
    self.saver.restore(self.sess, path)
  File "C:\Users\admin\Anaconda3\envs\tensorflow\lib\site-packages\tensorflow\python\training\saver.py", line 1755, in restore
    {self.saver_def.filename_tensor_name: save_path})
  File "C:\Users\admin\Anaconda3\envs\tensorflow\lib\site-packages\tensorflow\python\client\session.py", line 905, in run
    run_metadata_ptr)
  File "C:\Users\admin\Anaconda3\envs\tensorflow\lib\site-packages\tensorflow\python\client\session.py", line 1137, in _run
    feed_dict_tensor, options, run_metadata)
  File "C:\Users\admin\Anaconda3\envs\tensorflow\lib\site-packages\tensorflow\python\client\session.py", line 1355, in _do_run
    options, run_metadata)
  File "C:\Users\admin\Anaconda3\envs\tensorflow\lib\site-packages\tensorflow\python\client\session.py", line 1374, in _do_call
    raise type(e)(node_def, op, message)
tensorflow.python.framework.errors_impl.InvalidArgumentError: Assign requires shapes of both tensors to match. lhs shape= [1,1,512,18] rhs shape= [1,1,512,12]
	 [[Node: save/Assign_7 = Assign[T=DT_FLOAT, _class=["loc:@rpn_cls/weights"], use_locking=true, validate_shape=true, _device="/job:localhost/replica:0/task:0/device:GPU:0"](rpn_cls/weights, save/RestoreV2/_35)]]
	 [[Node: save/RestoreV2/_10 = _Send[T=DT_FLOAT, client_terminated=false, recv_device="/job:localhost/replica:0/task:0/device:GPU:0", send_device="/job:localhost/replica:0/task:0/device:CPU:0", send_device_incarnation=1, tensor_name="edge_16_save/RestoreV2", _device="/job:localhost/replica:0/task:0/device:CPU:0"](save/RestoreV2:5)]]

Caused by op 'save/Assign_7', defined at:
  File "C:/Users/admin/Documents/GeneralProjectData/Projects/NeuralNetworks.TF/Net/GUI/Demo/Demo.py", line 457, in <module>
    main()
  File "C:/Users/admin/Documents/GeneralProjectData/Projects/NeuralNetworks.TF/Net/GUI/Demo/Demo.py", line 453, in main
    application.exec()
  File "C:/Users/admin/Documents/GeneralProjectData/Projects/NeuralNetworks.TF/Net/GUI/Demo/Demo.py", line 168, in OnLoadModelMetaClick
    result = self.TFSession.load_model(FullFolderNameToModel=folderName, FullMetaFileName=fullName)
  File "C:/Users/admin/Documents/GeneralProjectData/Projects/NeuralNetworks.TF/Net/GUI/Demo/Demo.py", line 371, in load_model
    self.saver = tf.train.import_meta_graph(FullMetaFileName)
  File "C:\Users\admin\Anaconda3\envs\tensorflow\lib\site-packages\tensorflow\python\training\saver.py", line 1909, in import_meta_graph
    **kwargs)
  File "C:\Users\admin\Anaconda3\envs\tensorflow\lib\site-packages\tensorflow\python\framework\meta_graph.py", line 737, in import_scoped_meta_graph
    producer_op_list=producer_op_list)
  File "C:\Users\admin\Anaconda3\envs\tensorflow\lib\site-packages\tensorflow\python\util\deprecation.py", line 432, in new_func
    return func(*args, **kwargs)
  File "C:\Users\admin\Anaconda3\envs\tensorflow\lib\site-packages\tensorflow\python\framework\importer.py", line 553, in import_graph_def
    op_def=op_def)
  File "C:\Users\admin\Anaconda3\envs\tensorflow\lib\site-packages\tensorflow\python\framework\ops.py", line 3271, in create_op
    op_def=op_def)
  File "C:\Users\admin\Anaconda3\envs\tensorflow\lib\site-packages\tensorflow\python\framework\ops.py", line 1650, in __init__
    self._traceback = self._graph._extract_stack()  # pylint: disable=protected-access

InvalidArgumentError (see above for traceback): Assign requires shapes of both tensors to match. lhs shape= [1,1,512,18] rhs shape= [1,1,512,12]
	 [[Node: save/Assign_7 = Assign[T=DT_FLOAT, _class=["loc:@rpn_cls/weights"], use_locking=true, validate_shape=true, _device="/job:localhost/replica:0/task:0/device:GPU:0"](rpn_cls/weights, save/RestoreV2/_35)]]
	 [[Node: save/RestoreV2/_10 = _Send[T=DT_FLOAT, client_terminated=false, recv_device="/job:localhost/replica:0/task:0/device:GPU:0", send_device="/job:localhost/replica:0/task:0/device:CPU:0", send_device_incarnation=1, tensor_name="edge_16_save/RestoreV2", _device="/job:localhost/replica:0/task:0/device:CPU:0"](save/RestoreV2:5)]]




Loading model.

'TFSessionHolder' object has no attribute 'y'Traceback (most recent call last):
  File "C:/Users/admin/Documents/GeneralProjectData/Projects/NeuralNetworks.TF/Net/GUI/Demo/Demo.py", line 403, in evaluate
    self.prediction = self.y.eval(
AttributeError: 'TFSessionHolder' object has no attribute 'y'
'NoneType' object is not iterableTraceback (most recent call last):
  File "C:/Users/admin/Documents/GeneralProjectData/Projects/NeuralNetworks.TF/Net/GUI/Demo/Demo.py", line 183, in OnRecognizeClick
    result, coord, scores = self.TFSession.evaluate(self.imageContainer.image_array)
TypeError: 'NoneType' object is not iterable



Loading model.




Loading model.




Loading model.




Loading model.




Loading model.

Assign requires shapes of both tensors to match. lhs shape= [18] rhs shape= [12]
	 [[Node: save/Assign_4 = Assign[T=DT_FLOAT, _class=["loc:@rpn_cls/biases"], use_locking=true, validate_shape=true, _device="/job:localhost/replica:0/task:0/device:GPU:0"](rpn_cls/biases, save/RestoreV2/_33)]]

Caused by op 'save/Assign_4', defined at:
  File "C:/Users/admin/Documents/GeneralProjectData/Projects/NeuralNetworks.TF/Net/GUI/Demo/Demo.py", line 456, in <module>
    main()
  File "C:/Users/admin/Documents/GeneralProjectData/Projects/NeuralNetworks.TF/Net/GUI/Demo/Demo.py", line 452, in main
    application.exec()
  File "C:/Users/admin/Documents/GeneralProjectData/Projects/NeuralNetworks.TF/Net/GUI/Demo/Demo.py", line 168, in OnLoadModelMetaClick
    result = self.TFSession.load_model(FullFolderNameToModel=folderName, FullMetaFileName=fullName)
  File "C:/Users/admin/Documents/GeneralProjectData/Projects/NeuralNetworks.TF/Net/GUI/Demo/Demo.py", line 370, in load_model
    self.saver = tf.train.import_meta_graph(FullMetaFileName)
  File "C:\Users\admin\Anaconda3\envs\tensorflow\lib\site-packages\tensorflow\python\training\saver.py", line 1909, in import_meta_graph
    **kwargs)
  File "C:\Users\admin\Anaconda3\envs\tensorflow\lib\site-packages\tensorflow\python\framework\meta_graph.py", line 737, in import_scoped_meta_graph
    producer_op_list=producer_op_list)
  File "C:\Users\admin\Anaconda3\envs\tensorflow\lib\site-packages\tensorflow\python\util\deprecation.py", line 432, in new_func
    return func(*args, **kwargs)
  File "C:\Users\admin\Anaconda3\envs\tensorflow\lib\site-packages\tensorflow\python\framework\importer.py", line 553, in import_graph_def
    op_def=op_def)
  File "C:\Users\admin\Anaconda3\envs\tensorflow\lib\site-packages\tensorflow\python\framework\ops.py", line 3271, in create_op
    op_def=op_def)
  File "C:\Users\admin\Anaconda3\envs\tensorflow\lib\site-packages\tensorflow\python\framework\ops.py", line 1650, in __init__
    self._traceback = self._graph._extract_stack()  # pylint: disable=protected-access

InvalidArgumentError (see above for traceback): Assign requires shapes of both tensors to match. lhs shape= [18] rhs shape= [12]
	 [[Node: save/Assign_4 = Assign[T=DT_FLOAT, _class=["loc:@rpn_cls/biases"], use_locking=true, validate_shape=true, _device="/job:localhost/replica:0/task:0/device:GPU:0"](rpn_cls/biases, save/RestoreV2/_33)]]
Traceback (most recent call last):
  File "C:\Users\admin\Anaconda3\envs\tensorflow\lib\site-packages\tensorflow\python\client\session.py", line 1361, in _do_call
    return fn(*args)
  File "C:\Users\admin\Anaconda3\envs\tensorflow\lib\site-packages\tensorflow\python\client\session.py", line 1340, in _run_fn
    target_list, status, run_metadata)
  File "C:\Users\admin\Anaconda3\envs\tensorflow\lib\site-packages\tensorflow\python\framework\errors_impl.py", line 516, in __exit__
    c_api.TF_GetCode(self.status.status))
tensorflow.python.framework.errors_impl.InvalidArgumentError: Assign requires shapes of both tensors to match. lhs shape= [18] rhs shape= [12]
	 [[Node: save/Assign_4 = Assign[T=DT_FLOAT, _class=["loc:@rpn_cls/biases"], use_locking=true, validate_shape=true, _device="/job:localhost/replica:0/task:0/device:GPU:0"](rpn_cls/biases, save/RestoreV2/_33)]]

During handling of the above exception, another exception occurred:

Traceback (most recent call last):
  File "C:/Users/admin/Documents/GeneralProjectData/Projects/NeuralNetworks.TF/Net/GUI/Demo/Demo.py", line 374, in load_model
    self.saver.restore(self.sess, path)
  File "C:\Users\admin\Anaconda3\envs\tensorflow\lib\site-packages\tensorflow\python\training\saver.py", line 1755, in restore
    {self.saver_def.filename_tensor_name: save_path})
  File "C:\Users\admin\Anaconda3\envs\tensorflow\lib\site-packages\tensorflow\python\client\session.py", line 905, in run
    run_metadata_ptr)
  File "C:\Users\admin\Anaconda3\envs\tensorflow\lib\site-packages\tensorflow\python\client\session.py", line 1137, in _run
    feed_dict_tensor, options, run_metadata)
  File "C:\Users\admin\Anaconda3\envs\tensorflow\lib\site-packages\tensorflow\python\client\session.py", line 1355, in _do_run
    options, run_metadata)
  File "C:\Users\admin\Anaconda3\envs\tensorflow\lib\site-packages\tensorflow\python\client\session.py", line 1374, in _do_call
    raise type(e)(node_def, op, message)
tensorflow.python.framework.errors_impl.InvalidArgumentError: Assign requires shapes of both tensors to match. lhs shape= [18] rhs shape= [12]
	 [[Node: save/Assign_4 = Assign[T=DT_FLOAT, _class=["loc:@rpn_cls/biases"], use_locking=true, validate_shape=true, _device="/job:localhost/replica:0/task:0/device:GPU:0"](rpn_cls/biases, save/RestoreV2/_33)]]

Caused by op 'save/Assign_4', defined at:
  File "C:/Users/admin/Documents/GeneralProjectData/Projects/NeuralNetworks.TF/Net/GUI/Demo/Demo.py", line 456, in <module>
    main()
  File "C:/Users/admin/Documents/GeneralProjectData/Projects/NeuralNetworks.TF/Net/GUI/Demo/Demo.py", line 452, in main
    application.exec()
  File "C:/Users/admin/Documents/GeneralProjectData/Projects/NeuralNetworks.TF/Net/GUI/Demo/Demo.py", line 168, in OnLoadModelMetaClick
    result = self.TFSession.load_model(FullFolderNameToModel=folderName, FullMetaFileName=fullName)
  File "C:/Users/admin/Documents/GeneralProjectData/Projects/NeuralNetworks.TF/Net/GUI/Demo/Demo.py", line 370, in load_model
    self.saver = tf.train.import_meta_graph(FullMetaFileName)
  File "C:\Users\admin\Anaconda3\envs\tensorflow\lib\site-packages\tensorflow\python\training\saver.py", line 1909, in import_meta_graph
    **kwargs)
  File "C:\Users\admin\Anaconda3\envs\tensorflow\lib\site-packages\tensorflow\python\framework\meta_graph.py", line 737, in import_scoped_meta_graph
    producer_op_list=producer_op_list)
  File "C:\Users\admin\Anaconda3\envs\tensorflow\lib\site-packages\tensorflow\python\util\deprecation.py", line 432, in new_func
    return func(*args, **kwargs)
  File "C:\Users\admin\Anaconda3\envs\tensorflow\lib\site-packages\tensorflow\python\framework\importer.py", line 553, in import_graph_def
    op_def=op_def)
  File "C:\Users\admin\Anaconda3\envs\tensorflow\lib\site-packages\tensorflow\python\framework\ops.py", line 3271, in create_op
    op_def=op_def)
  File "C:\Users\admin\Anaconda3\envs\tensorflow\lib\site-packages\tensorflow\python\framework\ops.py", line 1650, in __init__
    self._traceback = self._graph._extract_stack()  # pylint: disable=protected-access

InvalidArgumentError (see above for traceback): Assign requires shapes of both tensors to match. lhs shape= [18] rhs shape= [12]
	 [[Node: save/Assign_4 = Assign[T=DT_FLOAT, _class=["loc:@rpn_cls/biases"], use_locking=true, validate_shape=true, _device="/job:localhost/replica:0/task:0/device:GPU:0"](rpn_cls/biases, save/RestoreV2/_33)]]




Loading model.




Loading model.




Loading model.




Loading model.




Loading model.




Loading model.

'TFSessionHolder' object has no attribute 'y'Traceback (most recent call last):
  File "C:/Users/admin/Documents/GeneralProjectData/Projects/NeuralNetworks.TF/Net/GUI/Demo/Demo.py", line 403, in evaluate
    self.prediction = self.y.eval(
AttributeError: 'TFSessionHolder' object has no attribute 'y'
'NoneType' object is not iterableTraceback (most recent call last):
  File "C:/Users/admin/Documents/GeneralProjectData/Projects/NeuralNetworks.TF/Net/GUI/Demo/Demo.py", line 183, in OnRecognizeClick
    result, coord, scores = self.TFSession.evaluate(self.imageContainer.image_array)
TypeError: 'NoneType' object is not iterable



Loading model.




Loading model.




Loading model.




Loading model.




Loading model.




Loading model.




Loading model.

"The name 'inputs:0' refers to a Tensor which does not exist. The operation, 'inputs', does not exist in the graph."Traceback (most recent call last):
  File "C:/Users/admin/Documents/GeneralProjectData/Projects/NeuralNetworks.TF/Net/GUI/Demo/Demo.py", line 377, in load_model
    self.x = self.graph.get_tensor_by_name('inputs:0')
  File "C:\Users\admin\Anaconda3\envs\tensorflow\lib\site-packages\tensorflow\python\framework\ops.py", line 3635, in get_tensor_by_name
    return self.as_graph_element(name, allow_tensor=True, allow_operation=False)
  File "C:\Users\admin\Anaconda3\envs\tensorflow\lib\site-packages\tensorflow\python\framework\ops.py", line 3459, in as_graph_element
    return self._as_graph_element_locked(obj, allow_tensor, allow_operation)
  File "C:\Users\admin\Anaconda3\envs\tensorflow\lib\site-packages\tensorflow\python\framework\ops.py", line 3501, in _as_graph_element_locked
    "graph." % (repr(name), repr(op_name)))
KeyError: "The name 'inputs:0' refers to a Tensor which does not exist. The operation, 'inputs', does not exist in the graph."



Loading model.

You must feed a value for placeholder tensor 'Placeholder' with dtype float and shape [?,224,224,3]
	 [[Node: Placeholder = Placeholder[dtype=DT_FLOAT, shape=[?,224,224,3], _device="/job:localhost/replica:0/task:0/device:GPU:0"]()]]
	 [[Node: BoundingBoxTransform/clip_bboxes_1/concat/_101 = _Recv[client_terminated=false, recv_device="/job:localhost/replica:0/task:0/device:CPU:0", send_device="/job:localhost/replica:0/task:0/device:GPU:0", send_device_incarnation=1, tensor_name="edge_736_BoundingBoxTransform/clip_bboxes_1/concat", tensor_type=DT_FLOAT, _device="/job:localhost/replica:0/task:0/device:CPU:0"]()]]

Caused by op 'Placeholder', defined at:
  File "C:/Users/admin/Documents/GeneralProjectData/Projects/NeuralNetworks.TF/Net/GUI/Demo/Demo.py", line 456, in <module>
    main()
  File "C:/Users/admin/Documents/GeneralProjectData/Projects/NeuralNetworks.TF/Net/GUI/Demo/Demo.py", line 452, in main
    application.exec()
  File "C:/Users/admin/Documents/GeneralProjectData/Projects/NeuralNetworks.TF/Net/GUI/Demo/Demo.py", line 168, in OnLoadModelMetaClick
    result = self.TFSession.load_model(FullFolderNameToModel=folderName, FullMetaFileName=fullName)
  File "C:/Users/admin/Documents/GeneralProjectData/Projects/NeuralNetworks.TF/Net/GUI/Demo/Demo.py", line 371, in load_model
    self.saver = tf.train.import_meta_graph(FullMetaFileName)
  File "C:\Users\admin\Anaconda3\envs\tensorflow\lib\site-packages\tensorflow\python\training\saver.py", line 1909, in import_meta_graph
    **kwargs)
  File "C:\Users\admin\Anaconda3\envs\tensorflow\lib\site-packages\tensorflow\python\framework\meta_graph.py", line 737, in import_scoped_meta_graph
    producer_op_list=producer_op_list)
  File "C:\Users\admin\Anaconda3\envs\tensorflow\lib\site-packages\tensorflow\python\util\deprecation.py", line 432, in new_func
    return func(*args, **kwargs)
  File "C:\Users\admin\Anaconda3\envs\tensorflow\lib\site-packages\tensorflow\python\framework\importer.py", line 553, in import_graph_def
    op_def=op_def)
  File "C:\Users\admin\Anaconda3\envs\tensorflow\lib\site-packages\tensorflow\python\framework\ops.py", line 3271, in create_op
    op_def=op_def)
  File "C:\Users\admin\Anaconda3\envs\tensorflow\lib\site-packages\tensorflow\python\framework\ops.py", line 1650, in __init__
    self._traceback = self._graph._extract_stack()  # pylint: disable=protected-access

InvalidArgumentError (see above for traceback): You must feed a value for placeholder tensor 'Placeholder' with dtype float and shape [?,224,224,3]
	 [[Node: Placeholder = Placeholder[dtype=DT_FLOAT, shape=[?,224,224,3], _device="/job:localhost/replica:0/task:0/device:GPU:0"]()]]
	 [[Node: BoundingBoxTransform/clip_bboxes_1/concat/_101 = _Recv[client_terminated=false, recv_device="/job:localhost/replica:0/task:0/device:CPU:0", send_device="/job:localhost/replica:0/task:0/device:GPU:0", send_device_incarnation=1, tensor_name="edge_736_BoundingBoxTransform/clip_bboxes_1/concat", tensor_type=DT_FLOAT, _device="/job:localhost/replica:0/task:0/device:CPU:0"]()]]
Traceback (most recent call last):
  File "C:\Users\admin\Anaconda3\envs\tensorflow\lib\site-packages\tensorflow\python\client\session.py", line 1361, in _do_call
    return fn(*args)
  File "C:\Users\admin\Anaconda3\envs\tensorflow\lib\site-packages\tensorflow\python\client\session.py", line 1340, in _run_fn
    target_list, status, run_metadata)
  File "C:\Users\admin\Anaconda3\envs\tensorflow\lib\site-packages\tensorflow\python\framework\errors_impl.py", line 516, in __exit__
    c_api.TF_GetCode(self.status.status))
tensorflow.python.framework.errors_impl.InvalidArgumentError: You must feed a value for placeholder tensor 'Placeholder' with dtype float and shape [?,224,224,3]
	 [[Node: Placeholder = Placeholder[dtype=DT_FLOAT, shape=[?,224,224,3], _device="/job:localhost/replica:0/task:0/device:GPU:0"]()]]
	 [[Node: BoundingBoxTransform/clip_bboxes_1/concat/_101 = _Recv[client_terminated=false, recv_device="/job:localhost/replica:0/task:0/device:CPU:0", send_device="/job:localhost/replica:0/task:0/device:GPU:0", send_device_incarnation=1, tensor_name="edge_736_BoundingBoxTransform/clip_bboxes_1/concat", tensor_type=DT_FLOAT, _device="/job:localhost/replica:0/task:0/device:CPU:0"]()]]

During handling of the above exception, another exception occurred:

Traceback (most recent call last):
  File "C:/Users/admin/Documents/GeneralProjectData/Projects/NeuralNetworks.TF/Net/GUI/Demo/Demo.py", line 407, in evaluate
    self.is_train: False
  File "C:\Users\admin\Anaconda3\envs\tensorflow\lib\site-packages\tensorflow\python\framework\ops.py", line 656, in eval
    return _eval_using_default_session(self, feed_dict, self.graph, session)
  File "C:\Users\admin\Anaconda3\envs\tensorflow\lib\site-packages\tensorflow\python\framework\ops.py", line 4901, in _eval_using_default_session
    return session.run(tensors, feed_dict)
  File "C:\Users\admin\Anaconda3\envs\tensorflow\lib\site-packages\tensorflow\python\client\session.py", line 905, in run
    run_metadata_ptr)
  File "C:\Users\admin\Anaconda3\envs\tensorflow\lib\site-packages\tensorflow\python\client\session.py", line 1137, in _run
    feed_dict_tensor, options, run_metadata)
  File "C:\Users\admin\Anaconda3\envs\tensorflow\lib\site-packages\tensorflow\python\client\session.py", line 1355, in _do_run
    options, run_metadata)
  File "C:\Users\admin\Anaconda3\envs\tensorflow\lib\site-packages\tensorflow\python\client\session.py", line 1374, in _do_call
    raise type(e)(node_def, op, message)
tensorflow.python.framework.errors_impl.InvalidArgumentError: You must feed a value for placeholder tensor 'Placeholder' with dtype float and shape [?,224,224,3]
	 [[Node: Placeholder = Placeholder[dtype=DT_FLOAT, shape=[?,224,224,3], _device="/job:localhost/replica:0/task:0/device:GPU:0"]()]]
	 [[Node: BoundingBoxTransform/clip_bboxes_1/concat/_101 = _Recv[client_terminated=false, recv_device="/job:localhost/replica:0/task:0/device:CPU:0", send_device="/job:localhost/replica:0/task:0/device:GPU:0", send_device_incarnation=1, tensor_name="edge_736_BoundingBoxTransform/clip_bboxes_1/concat", tensor_type=DT_FLOAT, _device="/job:localhost/replica:0/task:0/device:CPU:0"]()]]

Caused by op 'Placeholder', defined at:
  File "C:/Users/admin/Documents/GeneralProjectData/Projects/NeuralNetworks.TF/Net/GUI/Demo/Demo.py", line 456, in <module>
    main()
  File "C:/Users/admin/Documents/GeneralProjectData/Projects/NeuralNetworks.TF/Net/GUI/Demo/Demo.py", line 452, in main
    application.exec()
  File "C:/Users/admin/Documents/GeneralProjectData/Projects/NeuralNetworks.TF/Net/GUI/Demo/Demo.py", line 168, in OnLoadModelMetaClick
    result = self.TFSession.load_model(FullFolderNameToModel=folderName, FullMetaFileName=fullName)
  File "C:/Users/admin/Documents/GeneralProjectData/Projects/NeuralNetworks.TF/Net/GUI/Demo/Demo.py", line 371, in load_model
    self.saver = tf.train.import_meta_graph(FullMetaFileName)
  File "C:\Users\admin\Anaconda3\envs\tensorflow\lib\site-packages\tensorflow\python\training\saver.py", line 1909, in import_meta_graph
    **kwargs)
  File "C:\Users\admin\Anaconda3\envs\tensorflow\lib\site-packages\tensorflow\python\framework\meta_graph.py", line 737, in import_scoped_meta_graph
    producer_op_list=producer_op_list)
  File "C:\Users\admin\Anaconda3\envs\tensorflow\lib\site-packages\tensorflow\python\util\deprecation.py", line 432, in new_func
    return func(*args, **kwargs)
  File "C:\Users\admin\Anaconda3\envs\tensorflow\lib\site-packages\tensorflow\python\framework\importer.py", line 553, in import_graph_def
    op_def=op_def)
  File "C:\Users\admin\Anaconda3\envs\tensorflow\lib\site-packages\tensorflow\python\framework\ops.py", line 3271, in create_op
    op_def=op_def)
  File "C:\Users\admin\Anaconda3\envs\tensorflow\lib\site-packages\tensorflow\python\framework\ops.py", line 1650, in __init__
    self._traceback = self._graph._extract_stack()  # pylint: disable=protected-access

InvalidArgumentError (see above for traceback): You must feed a value for placeholder tensor 'Placeholder' with dtype float and shape [?,224,224,3]
	 [[Node: Placeholder = Placeholder[dtype=DT_FLOAT, shape=[?,224,224,3], _device="/job:localhost/replica:0/task:0/device:GPU:0"]()]]
	 [[Node: BoundingBoxTransform/clip_bboxes_1/concat/_101 = _Recv[client_terminated=false, recv_device="/job:localhost/replica:0/task:0/device:CPU:0", send_device="/job:localhost/replica:0/task:0/device:GPU:0", send_device_incarnation=1, tensor_name="edge_736_BoundingBoxTransform/clip_bboxes_1/concat", tensor_type=DT_FLOAT, _device="/job:localhost/replica:0/task:0/device:CPU:0"]()]]

'NoneType' object is not iterableTraceback (most recent call last):
  File "C:/Users/admin/Documents/GeneralProjectData/Projects/NeuralNetworks.TF/Net/GUI/Demo/Demo.py", line 183, in OnRecognizeClick
    result, coord, scores = self.TFSession.evaluate(self.imageContainer.image_array)
TypeError: 'NoneType' object is not iterable



Loading model.




Loading model.

"The name 'inputs:0' refers to a Tensor which does not exist. The operation, 'inputs', does not exist in the graph."Traceback (most recent call last):
  File "C:/Users/admin/Documents/GeneralProjectData/Projects/NeuralNetworks.TF/Net/GUI/Demo/Demo.py", line 382, in load_model
    self.x = self.graph.get_tensor_by_name('inputs:0')
  File "C:\Users\admin\Anaconda3\envs\tensorflow\lib\site-packages\tensorflow\python\framework\ops.py", line 3635, in get_tensor_by_name
    return self.as_graph_element(name, allow_tensor=True, allow_operation=False)
  File "C:\Users\admin\Anaconda3\envs\tensorflow\lib\site-packages\tensorflow\python\framework\ops.py", line 3459, in as_graph_element
    return self._as_graph_element_locked(obj, allow_tensor, allow_operation)
  File "C:\Users\admin\Anaconda3\envs\tensorflow\lib\site-packages\tensorflow\python\framework\ops.py", line 3501, in _as_graph_element_locked
    "graph." % (repr(name), repr(op_name)))
KeyError: "The name 'inputs:0' refers to a Tensor which does not exist. The operation, 'inputs', does not exist in the graph."
'TFSessionHolder' object has no attribute 'y'Traceback (most recent call last):
  File "C:/Users/admin/Documents/GeneralProjectData/Projects/NeuralNetworks.TF/Net/GUI/Demo/Demo.py", line 409, in evaluate
    self.prediction = self.y.eval(
AttributeError: 'TFSessionHolder' object has no attribute 'y'
'NoneType' object is not iterableTraceback (most recent call last):
  File "C:/Users/admin/Documents/GeneralProjectData/Projects/NeuralNetworks.TF/Net/GUI/Demo/Demo.py", line 183, in OnRecognizeClick
    result, coord, scores = self.TFSession.evaluate(self.imageContainer.image_array)
TypeError: 'NoneType' object is not iterable



Loading model.




Loading model.




Loading model.




Loading model.

unhashable type: 'numpy.ndarray'Traceback (most recent call last):
  File "C:/Users/admin/Documents/GeneralProjectData/Projects/NeuralNetworks.TF/Net/GUI/Demo/Demo2.py", line 416, in evaluate
    print(COUNTRIES[self.prediction])
TypeError: unhashable type: 'numpy.ndarray'
'NoneType' object is not iterableTraceback (most recent call last):
  File "C:/Users/admin/Documents/GeneralProjectData/Projects/NeuralNetworks.TF/Net/GUI/Demo/Demo2.py", line 184, in OnRecognizeClick
    result, coord, labels, scores = self.TFSession.evaluate(self.imageContainer.image_array)
TypeError: 'NoneType' object is not iterable



Loading model.




Loading model.




Loading model.

unhashable type: 'numpy.ndarray'Traceback (most recent call last):
  File "C:/Users/admin/Documents/GeneralProjectData/Projects/NeuralNetworks.TF/Net/GUI/Demo/Demo2.py", line 422, in evaluate
    print(COUNTRIES[self.prediction])
TypeError: unhashable type: 'numpy.ndarray'
'NoneType' object is not iterableTraceback (most recent call last):
  File "C:/Users/admin/Documents/GeneralProjectData/Projects/NeuralNetworks.TF/Net/GUI/Demo/Demo2.py", line 184, in OnRecognizeClick
    result, coord, labels, scores = self.TFSession.evaluate(self.imageContainer.image_array)
TypeError: 'NoneType' object is not iterable



Loading model.

unhashable type: 'numpy.ndarray'Traceback (most recent call last):
  File "C:/Users/admin/Documents/GeneralProjectData/Projects/NeuralNetworks.TF/Net/GUI/Demo/Demo2.py", line 422, in evaluate
    print(COUNTRIES[self.prediction])
TypeError: unhashable type: 'numpy.ndarray'
'NoneType' object is not iterableTraceback (most recent call last):
  File "C:/Users/admin/Documents/GeneralProjectData/Projects/NeuralNetworks.TF/Net/GUI/Demo/Demo2.py", line 184, in OnRecognizeClick
    result, coord, labels, scores = self.TFSession.evaluate(self.imageContainer.image_array)
TypeError: 'NoneType' object is not iterable



Loading model.

unhashable type: 'numpy.ndarray'Traceback (most recent call last):
  File "C:/Users/admin/Documents/GeneralProjectData/Projects/NeuralNetworks.TF/Net/GUI/Demo/Demo2.py", line 422, in evaluate
    print(COUNTRIES[self.prediction])
TypeError: unhashable type: 'numpy.ndarray'
'NoneType' object is not iterableTraceback (most recent call last):
  File "C:/Users/admin/Documents/GeneralProjectData/Projects/NeuralNetworks.TF/Net/GUI/Demo/Demo2.py", line 184, in OnRecognizeClick
    result, coord, labels, scores = self.TFSession.evaluate(self.imageContainer.image_array)
TypeError: 'NoneType' object is not iterable
'TFSessionHolder' object has no attribute 'boxes'Traceback (most recent call last):
  File "C:/Users/admin/Documents/GeneralProjectData/Projects/NeuralNetworks.TF/Net/GUI/Demo/Demo2.py", line 407, in evaluate
    [self.boxes, self.labels, self.probs],
AttributeError: 'TFSessionHolder' object has no attribute 'boxes'
'NoneType' object is not iterableTraceback (most recent call last):
  File "C:/Users/admin/Documents/GeneralProjectData/Projects/NeuralNetworks.TF/Net/GUI/Demo/Demo2.py", line 184, in OnRecognizeClick
    result, coord, labels, scores = self.TFSession.evaluate(self.imageContainer.image_array)
TypeError: 'NoneType' object is not iterable



Loading model.

unhashable type: 'numpy.ndarray'Traceback (most recent call last):
  File "C:/Users/admin/Documents/GeneralProjectData/Projects/NeuralNetworks.TF/Net/GUI/Demo/Demo2.py", line 422, in evaluate
    print(COUNTRIES[self.prediction])
TypeError: unhashable type: 'numpy.ndarray'
'NoneType' object is not iterableTraceback (most recent call last):
  File "C:/Users/admin/Documents/GeneralProjectData/Projects/NeuralNetworks.TF/Net/GUI/Demo/Demo2.py", line 184, in OnRecognizeClick
    result, coord, labels, scores = self.TFSession.evaluate(self.imageContainer.image_array)
TypeError: 'NoneType' object is not iterable
unhashable type: 'numpy.ndarray'Traceback (most recent call last):
  File "C:/Users/admin/Documents/GeneralProjectData/Projects/NeuralNetworks.TF/Net/GUI/Demo/Demo2.py", line 422, in evaluate
    print(COUNTRIES[self.prediction])
TypeError: unhashable type: 'numpy.ndarray'
'NoneType' object is not iterableTraceback (most recent call last):
  File "C:/Users/admin/Documents/GeneralProjectData/Projects/NeuralNetworks.TF/Net/GUI/Demo/Demo2.py", line 184, in OnRecognizeClick
    result, coord, labels, scores = self.TFSession.evaluate(self.imageContainer.image_array)
TypeError: 'NoneType' object is not iterable



Loading model.




Loading model.

unhashable type: 'numpy.ndarray'Traceback (most recent call last):
  File "C:/Users/admin/Documents/GeneralProjectData/Projects/NeuralNetworks.TF/Net/GUI/Demo/Demo2.py", line 422, in evaluate
    print(COUNTRIES[self.classes])
TypeError: unhashable type: 'numpy.ndarray'
'NoneType' object is not iterableTraceback (most recent call last):
  File "C:/Users/admin/Documents/GeneralProjectData/Projects/NeuralNetworks.TF/Net/GUI/Demo/Demo2.py", line 184, in OnRecognizeClick
    result, coord, labels, scores = self.TFSession.evaluate(self.imageContainer.image_array)
TypeError: 'NoneType' object is not iterable



Loading model.




Loading model.




Loading model.

unhashable type: 'list'Traceback (most recent call last):
  File "C:/Users/admin/Documents/GeneralProjectData/Projects/NeuralNetworks.TF/Net/GUI/Demo/Demo2.py", line 418, in evaluate
    print(COUNTRIES[self.classes])
TypeError: unhashable type: 'list'
'NoneType' object is not iterableTraceback (most recent call last):
  File "C:/Users/admin/Documents/GeneralProjectData/Projects/NeuralNetworks.TF/Net/GUI/Demo/Demo2.py", line 184, in OnRecognizeClick
    result, coord, labels, scores = self.TFSession.evaluate(self.imageContainer.image_array)
TypeError: 'NoneType' object is not iterable



Loading model.

'TFSessionHolder' object has no attribute 'boxes'Traceback (most recent call last):
  File "C:/Users/admin/Documents/GeneralProjectData/Projects/NeuralNetworks.TF/Net/GUI/Demo/Demo2.py", line 407, in evaluate
    [self.boxes, self.labels, self.probs],
AttributeError: 'TFSessionHolder' object has no attribute 'boxes'
'NoneType' object is not iterableTraceback (most recent call last):
  File "C:/Users/admin/Documents/GeneralProjectData/Projects/NeuralNetworks.TF/Net/GUI/Demo/Demo2.py", line 184, in OnRecognizeClick
    result, coord, labels, scores = self.TFSession.evaluate(self.imageContainer.image_array)
TypeError: 'NoneType' object is not iterable
'TFSessionHolder' object has no attribute 'boxes'Traceback (most recent call last):
  File "C:/Users/admin/Documents/GeneralProjectData/Projects/NeuralNetworks.TF/Net/GUI/Demo/Demo2.py", line 407, in evaluate
    [self.boxes, self.labels, self.probs],
AttributeError: 'TFSessionHolder' object has no attribute 'boxes'
'NoneType' object is not iterableTraceback (most recent call last):
  File "C:/Users/admin/Documents/GeneralProjectData/Projects/NeuralNetworks.TF/Net/GUI/Demo/Demo2.py", line 184, in OnRecognizeClick
    result, coord, labels, scores = self.TFSession.evaluate(self.imageContainer.image_array)
TypeError: 'NoneType' object is not iterable



Loading model.

'Frame' object has no attribute 'image_array'Traceback (most recent call last):
  File "C:/Users/admin/Documents/GeneralProjectData/Projects/NeuralNetworks.TF/Net/GUI/Demo/Demo2.py", line 184, in OnRecognizeClick
    result, coord, labels, scores = self.TFSession.evaluate(self.imageContainer.image_array)
AttributeError: 'Frame' object has no attribute 'image_array'



Loading model.

10Traceback (most recent call last):
  File "C:/Users/admin/Documents/GeneralProjectData/Projects/NeuralNetworks.TF/Net/GUI/Demo/Demo2.py", line 418, in evaluate
    print(COUNTRIES[10])
KeyError: 10
'NoneType' object is not iterableTraceback (most recent call last):
  File "C:/Users/admin/Documents/GeneralProjectData/Projects/NeuralNetworks.TF/Net/GUI/Demo/Demo2.py", line 184, in OnRecognizeClick
    result, coord, labels, scores = self.TFSession.evaluate(self.imageContainer.image_array)
TypeError: 'NoneType' object is not iterable



Loading model.




Loading model.




Loading model.




Loading model.




Loading model.

'TFSessionHolder' object has no attribute 'boxes'Traceback (most recent call last):
  File "C:/Users/admin/Documents/GeneralProjectData/Projects/NeuralNetworks.TF/Net/GUI/Demo/Demo2.py", line 407, in evaluate
    [self.boxes, self.labels, self.probs],
AttributeError: 'TFSessionHolder' object has no attribute 'boxes'
'NoneType' object is not iterableTraceback (most recent call last):
  File "C:/Users/admin/Documents/GeneralProjectData/Projects/NeuralNetworks.TF/Net/GUI/Demo/Demo2.py", line 184, in OnRecognizeClick
    result, coord, labels, scores = self.TFSession.evaluate(self.imageContainer.image_array)
TypeError: 'NoneType' object is not iterable



Loading model.




Loading model.




Loading model.




Loading model.




Loading model.




Loading model.




Loading model.




Loading model.




Loading model.




Loading model.




Loading model.




Loading model.




Loading model.




Loading model.




Loading model.




Loading model.




Loading model.




Loading model.




Loading model.




Loading model.




Loading model.




Loading model.




Loading model.




Loading model.




Loading model.




Loading model.




Loading model.




Loading model.




Loading model.




Loading model.

